Workbook

Sheet Explicit Short
A1: query_id | B1: query | C1: ground_truth_ranked_1 | D1: ground_truth_ranked_2 | E1: ground_truth_ranked_3 | F1: Explanation reasoning
A2: Q1 | B2: Sistem belum memiliki perlindungan terhadap malware yang memadai. Selain itu, tidak terdapat aktivitas pemantauan yang konsisten untuk mendeteksi ancaman. | C2: A.8.7 | D2: A.8.16 | F2: GT1: Perlindungan terhadap malware | GT2: Aktivitas pemantauan
A3: Q2 | B3: Persyaratan keamanan aplikasi belum terdefinisi dengan jelas, sehingga berpotensi menyebabkan kerentanan keamanan. | C3: A.8.26 | F3: GT1: Persyaratan keamanan aplikasi
A4: Q3 | B4: Kontrol masuk fisik belum diterapkan secara optimal. keamanan pengkabelan belum memenuhi standar yang ditetapkan. keamanan informasi dalam perjanjian pemasok belum memenuhi standar yang ditetapkan. | C4: A.7.2 | D4: A.7.12 | E4: A.5.20 | F4: GT1: Kontrol masuk fisik | GT2: Keamanan pengkabelan | GT3: Keamanan informasi dalam perjanjian pemasok
A5: Q4 | B5: Penyaringan belum sesuai dengan standar keamanan. Selain itu, kebijakan keamanan informasi belum diterapkan secara efektif di seluruh organisasi. | C5: A.6.1 | D5: A.5.1 | F5: GT1: Penyaringan | GT2: Kebijakan keamanan informasi
A6: Q5 | B6: Keamanan informasi selama gangguan belum memenuhi standar yang ditetapkan, sehingga berpotensi menyebabkan kerentanan keamanan. | C6: A.5.29 | F6: GT1: Keamanan informasi selama gangguan
A7: Q6 | B7: Penggunaan informasi dan aset terkait yang dapat diterima belum dilakukan sesuai standar. prosedur pengembalian aset belum dijalankan dengan baik. inventarisasi informasi dan aset terkait lainnya aset belum dilakukan secara menyeluruh. | C7: A.5.10 | D7: A.5.11 | E7: A.5.9 | F7: GT1: Penggunaan informasi dan aset terkait yang dapat diterima | GT2: Pengembalian aset | GT3: Inventarisasi informasi dan aset terkait lainnya
A8: Q7 | B8: Manajemen konfigurasi belum dilakukan sesuai standar. Selain itu, sistem belum memiliki perlindungan terhadap malware yang memadai. | C8: A.8.9 | D8: A.8.7 | F8: GT1: Manajemen konfigurasi | GT2: Perlindungan terhadap malware
A9: Q8 | B9: Manajemen kerentanan teknis belum dilakukan sesuai standar, sehingga berpotensi menyebabkan kerentanan keamanan. | C9: A.8.8 | F9: GT1: Manajemen kerentanan teknis
A10: Q9 | B10: Manajemen kapasitas belum dilakukan sesuai standar. akses ke kode sumber belum diatur dengan tepat. mekanisme autentikasi yang aman belum cukup kuat. | C10: A.8.6 | D10: A.8.4 | E10: A.8.5 | F10: GT1: Manajemen kapasitas | GT2: Akses ke kode sumber | GT3: Autentikasi yang aman
A11: Q10 | B11: Sistem belum memiliki perlindungan sistem informasi selama pengujian audit yang memadai. Selain itu, informasi pengujian belum dilakukan secara rutin. | C11: A.8.34 | D11: A.8.33 | F11: GT1: Perlindungan sistem informasi selama pengujian audit | GT2: Informasi pengujian
A12: Q11 | B12: Manajemen perubahan belum dilakukan sesuai standar, sehingga berpotensi menyebabkan kerentanan keamanan. | C12: A.8.32 | F12: GT1: Manajemen perubahan
A13: Q12 | B13: Pemisahan lingkungan pengembangan, pengujian, dan produksi belum dilakukan secara rutin. instalasi perangkat lunak pada sistem operasional belum sesuai dengan standar keamanan. penggunaan program utilitas istimewa belum dilakukan sesuai standar. | C13: A.8.31 | D13: A.8.19 | E13: A.8.18 | F13: GT1: Pemisahan lingkungan pengembangan, pengujian, dan produksi | GT2: Instalasi perangkat lunak pada sistem operasional | GT3: Penggunaan program utilitas istimewa
A14: Q13 | B14: Pengembangan yang dialihdayakan belum sesuai dengan standar keamanan. Selain itu, siklus hidup pengembangan yang aman belum sesuai dengan standar keamanan. | C14: A.8.30 | D14: A.8.25 | F14: GT1: Pengembangan yang dialihdayakan | GT2: Siklus hidup pengembangan yang aman
A15: Q14 | B15: Pembatasan akses informasi belum diatur dengan tepat, sehingga berpotensi menyebabkan kerentanan keamanan. | C15: A.8.3 | F15: GT1: Pembatasan akses informasi
A16: Q15 | B16: Pengujian keamanan dalam pengembangan dan penerimaan belum memenuhi standar yang ditetapkan. prinsip rekayasa dan arsitektur sistem yang aman belum sesuai dengan standar keamanan. pengkodean yang aman belum sesuai dengan standar keamanan. | C16: A.8.29 | D16: A.8.27 | E16: A.8.28 | F16: GT1: Pengujian keamanan dalam pengembangan dan penerimaan | GT2: Prinsip rekayasa dan arsitektur sistem yang aman | GT3: Pengkodean yang aman
A17: Q16 | B17: Penggunaan kriptografi belum dilakukan sesuai standar. Selain itu, persyaratan keamanan aplikasi belum terdefinisi dengan jelas. | C17: A.8.24 | D17: A.8.26 | F17: GT1: Penggunaan kriptografi | GT2: Persyaratan keamanan aplikasi
A18: Q17 | B18: Penyaringan web belum sesuai dengan standar keamanan, sehingga berpotensi menyebabkan kerentanan keamanan. | C18: A.8.23 | F18: GT1: Penyaringan web
A19: Q18 | B19: Pemisahan jaringan belum sesuai dengan standar keamanan. keamanan jaringan belum memenuhi standar yang ditetapkan. keamanan layanan jaringan belum memenuhi standar yang ditetapkan. | C19: A.8.22 | D19: A.8.20 | E19: A.8.21 | F19: GT1: Pemisahan jaringan | GT2: Keamanan jaringan | GT3: Keamanan layanan jaringan
A20: Q19 | B20: Hak akses istimewa belum diatur dengan tepat. Selain itu, pencatatan log belum sesuai dengan standar keamanan. | C20: A.8.2 | D20: A.8.15 | F20: GT1: Hak akses istimewa | GT2: Pencatatan log
A21: Q20 | B21: Sinkronisasi jam belum sesuai dengan standar keamanan, sehingga berpotensi menyebabkan kerentanan keamanan. | C21: A.8.17 | F21: GT1: Sinkronisasi jam
A22: Q21 | B22: Redundansi fasilitas pemrosesan informasi belum sesuai dengan standar keamanan. backup informasi belum sesuai dengan standar keamanan. penghapusan informasi belum sesuai dengan standar keamanan. | C22: A.8.14 | D22: A.8.13 | E22: A.8.10 | F22: GT1: Redundansi fasilitas pemrosesan informasi | GT2: Backup informasi | GT3: Penghapusan informasi
A23: Q22 | B23: Pencegahan kebocoran data belum sesuai dengan standar keamanan. Selain itu, penyamaran data belum sesuai dengan standar keamanan. | C23: A.8.12 | D23: A.8.11 | F23: GT1: Pencegahan kebocoran data | GT2: Penyamaran data
A24: Q23 | B24: Perangkat titik akhir pengguna belum sesuai dengan standar keamanan, sehingga berpotensi menyebabkan kerentanan keamanan. | C24: A.8.1 | F24: GT1: Perangkat titik akhir pengguna
A25: Q24 | B25: Keamanan aset di luar lokasi belum memenuhi standar yang ditetapkan. sistem belum memiliki penempatan dan perlindungan peralatan yang memadai. meja bersih dan layar bersih belum sesuai dengan standar keamanan. | C25: A.7.9 | D25: A.7.8 | E25: A.7.7 | F25: GT1: Keamanan aset di luar lokasi | GT2: Penempatan dan perlindungan peralatan | GT3: Meja bersih dan layar bersih
A26: Q25 | B26: Bekerja di area aman belum sesuai dengan standar keamanan. Selain itu, mengamankan kantor, ruangan, dan fasilitas belum sesuai dengan standar keamanan. | C26: A.7.6 | D26: A.7.3 | F26: GT1: Bekerja di area aman | GT2: Mengamankan kantor, ruangan, dan fasilitas
A27: Q26 | B27: Sistem belum memiliki perlindungan terhadap ancaman fisik dan lingkungan yang memadai, sehingga berpotensi menyebabkan kerentanan keamanan. | C27: A.7.5 | F27: GT1: Perlindungan terhadap ancaman fisik dan lingkungan
A28: Q27 | B28: Tidak terdapat pemantauan keamanan fisik yang konsisten untuk mendeteksi ancaman. kontrol masuk fisik belum diterapkan secara optimal. perimeter keamanan fisik belum memenuhi standar yang ditetapkan. | C28: A.7.4 | D28: A.7.2 | E28: A.7.1 | F28: GT1: Pemantauan keamanan fisik | GT2: Kontrol masuk fisik | GT3: Perimeter keamanan fisik
A29: Q28 | B29: Pembuangan atau penggunaan kembali peralatan secara aman belum dilakukan sesuai standar. Selain itu, media penyimpanan belum sesuai dengan standar keamanan. | C29: A.7.14 | D29: A.7.10 | F29: GT1: Pembuangan atau penggunaan kembali peralatan secara aman | GT2: Media penyimpanan
A30: Q29 | B30: Pemeliharaan peralatan belum sesuai dengan standar keamanan, sehingga berpotensi menyebabkan kerentanan keamanan. | C30: A.7.13 | F30: GT1: Pemeliharaan peralatan
A31: Q30 | B31: Utilitas pendukung belum sesuai dengan standar keamanan. keamanan pengkabelan belum memenuhi standar yang ditetapkan. kesiapan tik untuk kelangsungan bisnis belum sesuai dengan standar keamanan. | C31: A.7.11 | D31: A.7.12 | E31: A.5.30 | F31: GT1: Utilitas pendukung | GT2: Keamanan pengkabelan | GT3: Kesiapan TIK untuk kelangsungan bisnis
A32: Q31 | B32: Pelaporan peristiwa keamanan informasi belum memenuhi standar yang ditetapkan. Selain itu, perjanjian kerahasiaan atau non-disclosure belum sesuai dengan standar keamanan. | C32: A.6.8 | D32: A.6.6 | F32: GT1: Pelaporan peristiwa keamanan informasi | GT2: Perjanjian kerahasiaan atau non-disclosure
A33: Q32 | B33: Bekerja jarak jauh belum sesuai dengan standar keamanan, sehingga berpotensi menyebabkan kerentanan keamanan. | C33: A.6.7 | F33: GT1: Bekerja jarak jauh
A34: Q33 | B34: Tanggung jawab setelah pemutusan atau perubahan hubungan kerja belum sesuai dengan standar keamanan. syarat dan ketentuan ketenagakerjaan belum sesuai dengan standar keamanan. kesadaran, pendidikan, dan pelatihan keamanan informasi belum memenuhi standar yang ditetapkan. | C34: A.6.5 | D34: A.6.2 | E34: A.6.3 | F34: GT1: Tanggung jawab setelah pemutusan atau perubahan hubungan kerja | GT2: Syarat dan ketentuan ketenagakerjaan | GT3: Kesadaran, pendidikan, dan pelatihan keamanan informasi
A35: Q34 | B35: Proses pendisiplinan belum sesuai dengan standar keamanan. Selain itu, penyaringan belum sesuai dengan standar keamanan. | C35: A.6.4 | D35: A.6.1 | F35: GT1: Proses pendisiplinan | GT2: Penyaringan
A36: Q35 | B36: Keamanan informasi dalam manajemen proyek belum dilakukan sesuai standar, sehingga berpotensi menyebabkan kerentanan keamanan. | C36: A.5.8 | F36: GT1: Keamanan informasi dalam manajemen proyek
A37: Q36 | B37: Intelijen ancaman belum sesuai dengan standar keamanan. kontak dengan kelompok kepentingan khusus belum sesuai dengan standar keamanan. kontak dengan otoritas belum sesuai dengan standar keamanan. | C37: A.5.7 | D37: A.5.6 | E37: A.5.5 | F37: GT1: Intelijen ancaman | GT2: Kontak dengan kelompok kepentingan khusus | GT3: Kontak dengan otoritas
A38: Q37 | B38: Tanggung jawab manajemen belum dilakukan sesuai standar. Selain itu, peran dan tanggung jawab keamanan informasi belum memenuhi standar yang ditetapkan. | C38: A.5.4 | D38: A.5.2 | F38: GT1: Tanggung jawab manajemen | GT2: Peran dan tanggung jawab keamanan informasi
A39: Q38 | B39: Prosedur operasional yang didokumentasikan belum sesuai dengan standar keamanan, sehingga berpotensi menyebabkan kerentanan keamanan. | C39: A.5.37 | F39: GT1: Prosedur operasional yang didokumentasikan
A40: Q39 | B40: Kepatuhan terhadap kebijakan dan standar keamanan informasi belum diterapkan secara efektif di seluruh organisasi. tinjauan independen keamanan informasi belum memenuhi standar yang ditetapkan. sistem belum memiliki privasi dan perlindungan data pribadi yang memadai. | C40: A.5.36 | D40: A.5.35 | E40: A.5.34 | F40: GT1: Kepatuhan terhadap kebijakan dan standar keamanan informasi | GT2: Tinjauan independen keamanan informasi | GT3: Privasi dan perlindungan data pribadi
...

Sheet Explicit Long
A1: query_id | B1: query | C1: ground_truth_ranked_1 | D1: ground_truth_ranked_2 | E1: ground_truth_ranked_3
A2: Q1 | B2: Untuk mendukung keberlangsungan operasional sistem informasi yang aman, organisasi perlu menyelenggarakan perlindungan terhadap malware secara konsisten dan berkesinambungan. Mekanisme tersebut mencakup memastikan informasi dan fasilitas pemrosesan informasi dilindungi dari malware serta pengendalian terhadap potensi risiko yang dapat mengganggu operasional. Dalam hubungannya dengan hal tersebut, pelaksanaan aktivitas pemantauan menjadi esensial dalam menjamin efektivitas pengendalian keamanan informasi. Pengendalian tersebut perlu didukung oleh komitmen seluruh unit kerja serta didokumentasikan dalam bentuk prosedur yang dapat ditinjau secara berkala. | C2: A.8.7 | D2: A.8.16 | F2: GT1: Perlindungan terhadap malware | GT2: Aktivitas pemantauan | GT3: No Value
A3: Q2 | B3: Dalam kerangka tata kelola keamanan informasi yang baik, organisasi wajib menerapkan persyaratan keamanan aplikasi secara konsisten dan berkesinambungan. Kegiatan ini meliputi memastikan semua persyaratan keamanan informasi diidentifikasi dan ditangani dalam pengembangan aplikasi sebagai bagian dari upaya perlindungan menyeluruh. Pengendalian tersebut perlu didukung oleh komitmen seluruh unit kerja serta didokumentasikan dalam bentuk prosedur yang dapat ditinjau secara berkala. | C3: A.8.26 | F3: GT1: Persyaratan keamanan aplikasi | GT2: No Value
A4: Q3 | B4: Untuk mendukung keberlangsungan operasional sistem informasi yang aman, perlu dilakukan kontrol masuk fisik yang memadai pada seluruh aspek operasional yang terkait. Kegiatan ini meliputi memastikan hanya personel yang berwenang yang dapat mengakses area aman sebagai bagian dari upaya perlindungan menyeluruh. Sejalan dengan hal itu, diperlukan penerapan keamanan pengkabelan yang terstruktur dan terdokumentasi dengan baik. Selain hal tersebut, pelaksanaan keamanan informasi dalam perjanjian pemasok perlu diintegrasikan ke dalam kerangka pengendalian yang telah ditetapkan. Oleh karena itu, pengendalian tersebut harus menjadi perhatian utama dalam kerangka manajemen risiko keamanan informasi organisasi. | C4: A.7.2 | D4: A.7.12 | E4: A.5.20 | F4: GT1: Kontrol masuk fisik | GT2: Keamanan pengkabelan | GT3: Keamanan informasi dalam perjanjian pemasok
A5: Q4 | B5: Dalam rangka memenuhi persyaratan keamanan informasi organisasi, diperlukan penerapan mekanisme penyaringan sesuai dengan ketentuan dan standar yang berlaku. Pelaksanaan penyaringan tersebut harus mencakup langkah-langkah preventif dan detektif yang terstruktur. Di samping itu, pelaksanaan kebijakan keamanan informasi menjadi esensial dalam menjamin efektivitas pengendalian keamanan informasi. Keterpaduan dalam penerapan pengendalian ini menjadi kunci dalam membangun sistem keamanan informasi yang tangguh dan andal. | C5: A.6.1 | D5: A.5.1 | F5: GT1: Penyaringan | GT2: Kebijakan keamanan informasi | GT3: No Value
A6: Q5 | B6: Guna menunjang keamanan dan keandalan sistem informasi organisasi, diperlukan penerapan keamanan informasi selama gangguan secara konsisten dan berkesinambungan. Kegiatan ini meliputi memastikan keamanan informasi dipertahankan selama gangguan operasional sebagai bagian dari upaya perlindungan menyeluruh. Implementasi pengendalian ini diharapkan mampu mengurangi risiko keamanan informasi serta meningkatkan kesiapan organisasi dalam menghadapi ancaman siber. | C6: A.5.29 | F6: GT1: Keamanan informasi selama gangguan | GT2: No Value
A7: Q6 | B7: Dalam kerangka tata kelola keamanan informasi yang baik, perlu diimplementasikan penggunaan informasi dan aset terkait yang dapat diterima yang memadai pada seluruh aspek operasional yang terkait. Pelaksanaannya mencakup serangkaian prosedur yang dirancang untuk meminimalkan risiko keamanan informasi. Lebih lanjut, organisasi wajib memastikan bahwa pengembalian aset dilakukan secara konsisten dan terukur. Dalam aspek terkait, inventarisasi informasi dan aset terkait lainnya juga perlu mendapat perhatian sebagai bagian dari upaya perlindungan menyeluruh. Oleh karena itu, pengendalian tersebut harus menjadi perhatian utama dalam kerangka manajemen risiko keamanan informasi organisasi. | C7: A.5.10 | D7: A.5.11 | E7: A.5.9 | F7: GT1: Penggunaan informasi dan aset terkait yang dapat diterima | GT2: Pengembalian aset | GT3: Inventarisasi informasi dan aset terkait lainnya
A8: Q7 | B8: Dalam rangka memenuhi persyaratan keamanan informasi organisasi, perlu diimplementasikan manajemen konfigurasi sesuai dengan ketentuan dan standar yang berlaku. Pelaksanaan manajemen konfigurasi tersebut harus mencakup langkah-langkah preventif dan detektif yang terstruktur. Selain itu, diperlukan penerapan perlindungan terhadap malware yang terstruktur dan terdokumentasi dengan baik. Implementasi pengendalian ini diharapkan mampu mengurangi risiko keamanan informasi serta meningkatkan kesiapan organisasi dalam menghadapi ancaman siber. | C8: A.8.9 | D8: A.8.7 | F8: GT1: Manajemen konfigurasi | GT2: Perlindungan terhadap malware | GT3: No Value
A9: Q8 | B9: Dalam kerangka tata kelola keamanan informasi yang baik, diperlukan pengelolaan manajemen kerentanan teknis yang memadai pada seluruh aspek operasional yang terkait. Pelaksanaannya mencakup serangkaian prosedur yang dirancang untuk meminimalkan risiko keamanan informasi. Implementasi pengendalian ini diharapkan mampu mengurangi risiko keamanan informasi serta meningkatkan kesiapan organisasi dalam menghadapi ancaman siber. | C9: A.8.8 | F9: GT1: Manajemen kerentanan teknis | GT2: No Value
A10: Q9 | B10: Sebagai bagian dari upaya menjaga integritas dan keamanan sistem informasi, harus dilaksanakan manajemen kapasitas yang memadai pada seluruh aspek operasional yang terkait. Pelaksanaannya mencakup serangkaian prosedur yang dirancang untuk meminimalkan risiko keamanan informasi. Berkaitan dengan aspek tersebut, akses ke kode sumber harus dilaksanakan secara sistematis sebagai bagian dari kerangka pengendalian internal. Dalam aspek terkait, autentikasi yang aman juga perlu mendapat perhatian sebagai bagian dari upaya perlindungan menyeluruh. Oleh karena itu, pengendalian tersebut harus menjadi perhatian utama dalam kerangka manajemen risiko keamanan informasi organisasi. | C10: A.8.6 | D10: A.8.4 | E10: A.8.5 | F10: GT1: Manajemen kapasitas | GT2: Akses ke kode sumber | GT3: Autentikasi yang aman
A11: Q10 | B11: Untuk memenuhi standar keamanan informasi yang berlaku, diperlukan pengelolaan perlindungan sistem informasi selama pengujian audit sesuai dengan ketentuan dan standar yang berlaku. Pelaksanaannya mencakup serangkaian prosedur yang dirancang untuk meminimalkan risiko keamanan informasi. Pada aspek lain, organisasi perlu menyelenggarakan informasi pengujian secara berkelanjutan untuk mendukung keberlangsungan operasional. Oleh karena itu, pengendalian tersebut harus menjadi perhatian utama dalam kerangka manajemen risiko keamanan informasi organisasi. | C11: A.8.34 | D11: A.8.33 | F11: GT1: Perlindungan sistem informasi selama pengujian audit | GT2: Informasi pengujian | GT3: No Value
A12: Q11 | B12: Dalam rangka menjamin keamanan sistem informasi di lingkungan organisasi, harus dilaksanakan manajemen perubahan secara konsisten dan berkesinambungan. Pelaksanaan manajemen perubahan tersebut harus mencakup langkah-langkah preventif dan detektif yang terstruktur. Dengan penerapan pengendalian yang konsisten, organisasi dapat memastikan bahwa keamanan informasi terjaga sesuai dengan standar yang ditetapkan. | C12: A.8.32 | F12: GT1: Manajemen perubahan | GT2: No Value
A13: Q12 | B13: Untuk memenuhi standar keamanan informasi yang berlaku, diperlukan penerapan pemisahan lingkungan pengembangan, pengujian, dan produksi yang memadai pada seluruh aspek operasional yang terkait. Pelaksanaan pemisahan lingkungan pengembangan, pengujian, dan produksi tersebut harus mencakup langkah-langkah preventif dan detektif yang terstruktur. Sejalan dengan hal itu, instalasi perangkat lunak pada sistem operasional harus dilaksanakan secara sistematis sebagai bagian dari kerangka pengendalian internal. Dalam aspek terkait, penggunaan program utilitas istimewa juga perlu mendapat perhatian sebagai bagian dari upaya perlindungan menyeluruh. Pengendalian tersebut perlu didukung oleh komitmen seluruh unit kerja serta didokumentasikan dalam bentuk prosedur yang dapat ditinjau secara berkala. | C13: A.8.31 | D13: A.8.19 | E13: A.8.18 | F13: GT1: Pemisahan lingkungan pengembangan, pengujian, dan produksi | GT2: Instalasi perangkat lunak pada sistem operasional | GT3: Penggunaan program utilitas istimewa
A14: Q13 | B14: Untuk memenuhi standar keamanan informasi yang berlaku, perlu diimplementasikan pengembangan yang dialihdayakan secara konsisten dan berkesinambungan. Pelaksanaannya mencakup serangkaian prosedur yang dirancang untuk meminimalkan risiko keamanan informasi. Pada aspek lain, organisasi wajib memastikan bahwa siklus hidup pengembangan yang aman dilakukan secara konsisten dan terukur. Penerapan seluruh pengendalian tersebut secara terintegrasi diperlukan guna mencapai tingkat keamanan informasi yang memadai. | C14: A.8.30 | D14: A.8.25 | F14: GT1: Pengembangan yang dialihdayakan | GT2: Siklus hidup pengembangan yang aman | GT3: No Value
A15: Q14 | B15: Dalam upaya mewujudkan pengelolaan keamanan informasi yang komprehensif, diperlukan penerapan mekanisme pembatasan akses informasi secara konsisten dan berkesinambungan. Mekanisme tersebut mencakup memastikan akses ke informasi dibatasi sesuai dengan kebijakan pengendalian akses serta pengendalian terhadap potensi risiko yang dapat mengganggu operasional. Hal ini sejalan dengan kebutuhan organisasi dalam memastikan bahwa seluruh aspek keamanan informasi dikelola secara sistematis dan terdokumentasi dengan baik. | C15: A.8.3 | F15: GT1: Pembatasan akses informasi | GT2: No Value
A16: Q15 | B16: Sebagai upaya untuk memitigasi risiko keamanan informasi, diperlukan pelaksanaan pengujian keamanan dalam pengembangan dan penerimaan secara konsisten dan berkesinambungan. Pelaksanaannya mencakup serangkaian prosedur yang dirancang untuk meminimalkan risiko keamanan informasi. Lebih lanjut, diperlukan penerapan prinsip rekayasa dan arsitektur sistem yang aman yang terstruktur dan terdokumentasi dengan baik. Selain hal tersebut, pelaksanaan pengkodean yang aman perlu diintegrasikan ke dalam kerangka pengendalian yang telah ditetapkan. Dengan penerapan pengendalian yang konsisten, organisasi dapat memastikan bahwa keamanan informasi terjaga sesuai dengan standar yang ditetapkan. | C16: A.8.29 | D16: A.8.27 | E16: A.8.28 | F16: GT1: Pengujian keamanan dalam pengembangan dan penerimaan | GT2: Prinsip rekayasa dan arsitektur sistem yang aman | GT3: Pengkodean yang aman
A17: Q16 | B17: Dalam rangka menjamin keamanan sistem informasi di lingkungan organisasi, diperlukan pengelolaan penggunaan kriptografi yang memadai pada seluruh aspek operasional yang terkait. Mekanisme tersebut mencakup memastikan penggunaan kriptografi yang tepat dan efektif untuk melindungi kerahasiaan, autentisitas, dan integritas informasi serta pengendalian terhadap potensi risiko yang dapat mengganggu operasional. Berkaitan dengan aspek tersebut, organisasi wajib memastikan bahwa persyaratan keamanan aplikasi dilakukan secara konsisten dan terukur. Dengan penerapan pengendalian yang konsisten, organisasi dapat memastikan bahwa keamanan informasi terjaga sesuai dengan standar yang ditetapkan. | C17: A.8.24 | D17: A.8.26 | F17: GT1: Penggunaan kriptografi | GT2: Persyaratan keamanan aplikasi | GT3: No Value
A18: Q17 | B18: Dalam kerangka tata kelola keamanan informasi yang baik, organisasi wajib menerapkan penyaringan web yang memadai pada seluruh aspek operasional yang terkait. Pelaksanaan penyaringan web tersebut harus mencakup langkah-langkah preventif dan detektif yang terstruktur. Pengendalian tersebut perlu didukung oleh komitmen seluruh unit kerja serta didokumentasikan dalam bentuk prosedur yang dapat ditinjau secara berkala. | C18: A.8.23 | F18: GT1: Penyaringan web | GT2: No Value
A19: Q18 | B19: Untuk mendukung keberlangsungan operasional sistem informasi yang aman, diperlukan penerapan pemisahan jaringan yang memadai pada seluruh aspek operasional yang terkait. Mekanisme tersebut mencakup membatasi dampak insiden keamanan melalui segmentasi jaringan serta pengendalian terhadap potensi risiko yang dapat mengganggu operasional. Di samping itu, keamanan jaringan harus dilaksanakan secara sistematis sebagai bagian dari kerangka pengendalian internal. Selain hal tersebut, pelaksanaan keamanan layanan jaringan perlu diintegrasikan ke dalam kerangka pengendalian yang telah ditetapkan. Oleh karena itu, pengendalian tersebut harus menjadi perhatian utama dalam kerangka manajemen risiko keamanan informasi organisasi. | C19: A.8.22 | D19: A.8.20 | E19: A.8.21 | F19: GT1: Pemisahan jaringan | GT2: Keamanan jaringan | GT3: Keamanan layanan jaringan
A20: Q19 | B20: Sebagai bagian dari upaya menjaga integritas dan keamanan sistem informasi, organisasi perlu menyelenggarakan hak akses istimewa secara konsisten dan berkesinambungan. Kegiatan ini meliputi membatasi dan mengendalikan alokasi serta penggunaan hak akses istimewa sebagai bagian dari upaya perlindungan menyeluruh. Berkaitan dengan aspek tersebut, pencatatan log harus dilaksanakan secara sistematis sebagai bagian dari kerangka pengendalian internal. Keterpaduan dalam penerapan pengendalian ini menjadi kunci dalam membangun sistem keamanan informasi yang tangguh dan andal. | C20: A.8.2 | D20: A.8.15 | F20: GT1: Hak akses istimewa | GT2: Pencatatan log | GT3: No Value
A21: Q20 | B21: Sebagai upaya untuk memitigasi risiko keamanan informasi, diperlukan penerapan sinkronisasi jam yang memadai pada seluruh aspek operasional yang terkait. Mekanisme tersebut mencakup memastikan semua sistem menggunakan waktu yang tersinkronisasi untuk korelasi log yang akurat serta pengendalian terhadap potensi risiko yang dapat mengganggu operasional. Hal ini sejalan dengan kebutuhan organisasi dalam memastikan bahwa seluruh aspek keamanan informasi dikelola secara sistematis dan terdokumentasi dengan baik. | C21: A.8.17 | F21: GT1: Sinkronisasi jam | GT2: No Value
A22: Q21 | B22: Dalam rangka menjamin keamanan sistem informasi di lingkungan organisasi, organisasi perlu menyelenggarakan redundansi fasilitas pemrosesan informasi secara konsisten dan berkesinambungan. Pelaksanaannya mencakup serangkaian prosedur yang dirancang untuk meminimalkan risiko keamanan informasi. Terkait dengan upaya tersebut, pelaksanaan backup informasi menjadi esensial dalam menjamin efektivitas pengendalian keamanan informasi. Dalam aspek terkait, penghapusan informasi juga perlu mendapat perhatian sebagai bagian dari upaya perlindungan menyeluruh. Pengendalian tersebut perlu didukung oleh komitmen seluruh unit kerja serta didokumentasikan dalam bentuk prosedur yang dapat ditinjau secara berkala. | C22: A.8.14 | D22: A.8.13 | E22: A.8.10 | F22: GT1: Redundansi fasilitas pemrosesan informasi | GT2: Backup informasi | GT3: Penghapusan informasi
A23: Q22 | B23: Untuk memenuhi standar keamanan informasi yang berlaku, organisasi wajib menyelenggarakan pencegahan kebocoran data secara konsisten dan berkesinambungan. Pelaksanaannya mencakup serangkaian prosedur yang dirancang untuk meminimalkan risiko keamanan informasi. Lebih lanjut, organisasi wajib memastikan bahwa penyamaran data dilakukan secara konsisten dan terukur. Hal ini sejalan dengan kebutuhan organisasi dalam memastikan bahwa seluruh aspek keamanan informasi dikelola secara sistematis dan terdokumentasi dengan baik. | C23: A.8.12 | D23: A.8.11 | F23: GT1: Pencegahan kebocoran data | GT2: Penyamaran data | GT3: No Value
A24: Q23 | B24: Sebagai bagian dari upaya menjaga integritas dan keamanan sistem informasi, organisasi wajib menyelenggarakan perangkat titik akhir pengguna yang memadai pada seluruh aspek operasional yang terkait. Mekanisme tersebut mencakup melindungi informasi yang disimpan, diproses, atau diakses melalui perangkat titik akhir pengguna serta pengendalian terhadap potensi risiko yang dapat mengganggu operasional. Dengan demikian, penerapan pengendalian tersebut menjadi bagian integral dalam menjaga keamanan dan keberlangsungan layanan sistem informasi organisasi. | C24: A.8.1 | F24: GT1: Perangkat titik akhir pengguna | GT2: No Value
A25: Q24 | B25: Dalam rangka memenuhi persyaratan keamanan informasi organisasi, perlu dilakukan keamanan aset di luar lokasi secara konsisten dan berkesinambungan. Pelaksanaan keamanan aset di luar lokasi tersebut harus mencakup langkah-langkah preventif dan detektif yang terstruktur. Selanjutnya, diperlukan penerapan penempatan dan perlindungan peralatan yang terstruktur dan terdokumentasi dengan baik. Dalam aspek terkait, meja bersih dan layar bersih juga perlu mendapat perhatian sebagai bagian dari upaya perlindungan menyeluruh. Dengan demikian, penerapan pengendalian tersebut menjadi bagian integral dalam menjaga keamanan dan keberlangsungan layanan sistem informasi organisasi. | C25: A.7.9 | D25: A.7.8 | E25: A.7.7 | F25: GT1: Keamanan aset di luar lokasi | GT2: Penempatan dan perlindungan peralatan | GT3: Meja bersih dan layar bersih
A26: Q25 | B26: Guna menunjang keamanan dan keandalan sistem informasi organisasi, diperlukan penerapan bekerja di area aman sesuai dengan ketentuan dan standar yang berlaku. Mekanisme tersebut mencakup mencegah kerusakan dan gangguan oleh personel yang bekerja di area aman serta pengendalian terhadap potensi risiko yang dapat mengganggu operasional. Pada aspek lain, mengamankan kantor, ruangan, dan fasilitas harus dilaksanakan secara sistematis sebagai bagian dari kerangka pengendalian internal. Penerapan seluruh pengendalian tersebut secara terintegrasi diperlukan guna mencapai tingkat keamanan informasi yang memadai. | C26: A.7.6 | D26: A.7.3 | F26: GT1: Bekerja di area aman | GT2: Mengamankan kantor, ruangan, dan fasilitas | GT3: No Value
A27: Q26 | B27: Dalam konteks pengelolaan keamanan informasi organisasi, diperlukan pelaksanaan perlindungan terhadap ancaman fisik dan lingkungan sesuai dengan ketentuan dan standar yang berlaku. Pelaksanaannya mencakup serangkaian prosedur yang dirancang untuk meminimalkan risiko keamanan informasi. Dengan demikian, penerapan pengendalian tersebut menjadi bagian integral dalam menjaga keamanan dan keberlangsungan layanan sistem informasi organisasi. | C27: A.7.5 | F27: GT1: Perlindungan terhadap ancaman fisik dan lingkungan | GT2: No Value
A28: Q27 | B28: Untuk mendukung keberlangsungan operasional sistem informasi yang aman, harus dilaksanakan pemantauan keamanan fisik secara konsisten dan berkesinambungan. Mekanisme tersebut mencakup mendeteksi dan mencegah akses fisik yang tidak sah melalui pemantauan berkelanjutan serta pengendalian terhadap potensi risiko yang dapat mengganggu operasional. Dalam konteks yang lebih luas, pelaksanaan kontrol masuk fisik menjadi esensial dalam menjamin efektivitas pengendalian keamanan informasi. Dalam aspek terkait, perimeter keamanan fisik juga perlu mendapat perhatian sebagai bagian dari upaya perlindungan menyeluruh. Penerapan seluruh pengendalian tersebut secara terintegrasi diperlukan guna mencapai tingkat keamanan informasi yang memadai. | C28: A.7.4 | D28: A.7.2 | E28: A.7.1 | F28: GT1: Pemantauan keamanan fisik | GT2: Kontrol masuk fisik | GT3: Perimeter keamanan fisik
A29: Q28 | B29: Untuk mendukung keberlangsungan operasional sistem informasi yang aman, organisasi wajib menyelenggarakan pembuangan atau penggunaan kembali peralatan secara aman sesuai dengan ketentuan dan standar yang berlaku. Kegiatan ini meliputi mencegah kebocoran informasi dari peralatan yang dibuang atau digunakan kembali sebagai bagian dari upaya perlindungan menyeluruh. Terkait dengan upaya tersebut, organisasi perlu menyelenggarakan media penyimpanan secara berkelanjutan untuk mendukung keberlangsungan operasional. Penerapan seluruh pengendalian tersebut secara terintegrasi diperlukan guna mencapai tingkat keamanan informasi yang memadai. | C29: A.7.14 | D29: A.7.10 | F29: GT1: Pembuangan atau penggunaan kembali peralatan secara aman | GT2: Media penyimpanan | GT3: No Value
A30: Q29 | B30: Dalam rangka menjamin keamanan sistem informasi di lingkungan organisasi, organisasi perlu menyelenggarakan pemeliharaan peralatan secara konsisten dan berkesinambungan. Kegiatan ini meliputi memastikan ketersediaan dan integritas peralatan melalui pemeliharaan yang tepat sebagai bagian dari upaya perlindungan menyeluruh. Pengendalian tersebut perlu didukung oleh komitmen seluruh unit kerja serta didokumentasikan dalam bentuk prosedur yang dapat ditinjau secara berkala. | C30: A.7.13 | F30: GT1: Pemeliharaan peralatan | GT2: No Value
A31: Q30 | B31: Dalam konteks pengelolaan keamanan informasi organisasi, harus dilaksanakan utilitas pendukung secara konsisten dan berkesinambungan. Pelaksanaan utilitas pendukung tersebut harus mencakup langkah-langkah preventif dan detektif yang terstruktur. Selanjutnya, diperlukan penerapan keamanan pengkabelan yang terstruktur dan terdokumentasi dengan baik. Selain hal tersebut, pelaksanaan kesiapan tik untuk kelangsungan bisnis perlu diintegrasikan ke dalam kerangka pengendalian yang telah ditetapkan. Dengan demikian, penerapan pengendalian tersebut menjadi bagian integral dalam menjaga keamanan dan keberlangsungan layanan sistem informasi organisasi. | C31: A.7.11 | D31: A.7.12 | E31: A.5.30 | F31: GT1: Utilitas pendukung | GT2: Keamanan pengkabelan | GT3: Kesiapan TIK untuk kelangsungan bisnis
A32: Q31 | B32: Guna menunjang keamanan dan keandalan sistem informasi organisasi, perlu dilakukan pelaporan peristiwa keamanan informasi yang memadai pada seluruh aspek operasional yang terkait. Pelaksanaannya mencakup serangkaian prosedur yang dirancang untuk meminimalkan risiko keamanan informasi. Terkait dengan upaya tersebut, diperlukan penerapan perjanjian kerahasiaan atau non-disclosure yang terstruktur dan terdokumentasi dengan baik. Dengan penerapan pengendalian yang konsisten, organisasi dapat memastikan bahwa keamanan informasi terjaga sesuai dengan standar yang ditetapkan. | C32: A.6.8 | D32: A.6.6 | F32: GT1: Pelaporan peristiwa keamanan informasi | GT2: Perjanjian kerahasiaan atau non-disclosure | GT3: No Value
A33: Q32 | B33: Guna menunjang keamanan dan keandalan sistem informasi organisasi, perlu diimplementasikan bekerja jarak jauh sesuai dengan ketentuan dan standar yang berlaku. Pelaksanaan bekerja jarak jauh tersebut harus mencakup langkah-langkah preventif dan detektif yang terstruktur. Keterpaduan dalam penerapan pengendalian ini menjadi kunci dalam membangun sistem keamanan informasi yang tangguh dan andal. | C33: A.6.7 | F33: GT1: Bekerja jarak jauh | GT2: No Value
A34: Q33 | B34: Sebagai upaya untuk memitigasi risiko keamanan informasi, perlu diimplementasikan tanggung jawab setelah pemutusan atau perubahan hubungan kerja yang memadai pada seluruh aspek operasional yang terkait. Mekanisme tersebut mencakup melindungi kepentingan organisasi setelah pemutusan atau perubahan hubungan kerja serta pengendalian terhadap potensi risiko yang dapat mengganggu operasional. Selain itu, syarat dan ketentuan ketenagakerjaan harus dilaksanakan secara sistematis sebagai bagian dari kerangka pengendalian internal. Pada dimensi lain, kesadaran, pendidikan, dan pelatihan keamanan informasi juga merupakan komponen penting yang harus diperhatikan dalam kerangka keamanan informasi. Dengan penerapan pengendalian yang konsisten, organisasi dapat memastikan bahwa keamanan informasi terjaga sesuai dengan standar yang ditetapkan. | C34: A.6.5 | D34: A.6.2 | E34: A.6.3 | F34: GT1: Tanggung jawab setelah pemutusan atau perubahan hubungan kerja | GT2: Syarat dan ketentuan ketenagakerjaan | GT3: Kesadaran, pendidikan, dan pelatihan keamanan informasi
A35: Q34 | B35: Dalam kerangka tata kelola keamanan informasi yang baik, organisasi perlu menyelenggarakan proses pendisiplinan yang memadai pada seluruh aspek operasional yang terkait. Pelaksanaannya mencakup serangkaian prosedur yang dirancang untuk meminimalkan risiko keamanan informasi. Dalam hubungannya dengan hal tersebut, pelaksanaan penyaringan menjadi esensial dalam menjamin efektivitas pengendalian keamanan informasi. Hal ini sejalan dengan kebutuhan organisasi dalam memastikan bahwa seluruh aspek keamanan informasi dikelola secara sistematis dan terdokumentasi dengan baik. | C35: A.6.4 | D35: A.6.1 | F35: GT1: Proses pendisiplinan | GT2: Penyaringan | GT3: No Value
A36: Q35 | B36: Untuk mendukung keberlangsungan operasional sistem informasi yang aman, diperlukan penerapan keamanan informasi dalam manajemen proyek yang memadai pada seluruh aspek operasional yang terkait. Pelaksanaannya mencakup serangkaian prosedur yang dirancang untuk meminimalkan risiko keamanan informasi. Oleh karena itu, pengendalian tersebut harus menjadi perhatian utama dalam kerangka manajemen risiko keamanan informasi organisasi. | C36: A.5.8 | F36: GT1: Keamanan informasi dalam manajemen proyek | GT2: No Value
A37: Q36 | B37: Dalam upaya mewujudkan pengelolaan keamanan informasi yang komprehensif, diperlukan penerapan intelijen ancaman secara konsisten dan berkesinambungan. Mekanisme tersebut mencakup mengumpulkan dan menganalisis informasi tentang ancaman keamanan informasi untuk mengambil tindakan pencegahan serta pengendalian terhadap potensi risiko yang dapat mengganggu operasional. Di samping itu, kontak dengan kelompok kepentingan khusus harus dilaksanakan secara sistematis sebagai bagian dari kerangka pengendalian internal. Pada dimensi lain, kontak dengan otoritas juga merupakan komponen penting yang harus diperhatikan dalam kerangka keamanan informasi. Dengan penerapan pengendalian yang konsisten, organisasi dapat memastikan bahwa keamanan informasi terjaga sesuai dengan standar yang ditetapkan. | C37: A.5.7 | D37: A.5.6 | E37: A.5.5 | F37: GT1: Intelijen ancaman | GT2: Kontak dengan kelompok kepentingan khusus | GT3: Kontak dengan otoritas
A38: Q37 | B38: Dalam konteks pengelolaan keamanan informasi organisasi, diperlukan pengelolaan tanggung jawab manajemen secara konsisten dan berkesinambungan. Pelaksanaan tanggung jawab manajemen tersebut harus mencakup langkah-langkah preventif dan detektif yang terstruktur. Pada aspek lain, diperlukan penerapan peran dan tanggung jawab keamanan informasi yang terstruktur dan terdokumentasi dengan baik. Dengan penerapan pengendalian yang konsisten, organisasi dapat memastikan bahwa keamanan informasi terjaga sesuai dengan standar yang ditetapkan. | C38: A.5.4 | D38: A.5.2 | F38: GT1: Tanggung jawab manajemen | GT2: Peran dan tanggung jawab keamanan informasi | GT3: No Value
A39: Q38 | B39: Guna menunjang keamanan dan keandalan sistem informasi organisasi, perlu dilakukan prosedur operasional yang didokumentasikan yang memadai pada seluruh aspek operasional yang terkait. Mekanisme tersebut mencakup memastikan operasi fasilitas pemrosesan informasi dilakukan dengan benar dan aman serta pengendalian terhadap potensi risiko yang dapat mengganggu operasional. Hal ini sejalan dengan kebutuhan organisasi dalam memastikan bahwa seluruh aspek keamanan informasi dikelola secara sistematis dan terdokumentasi dengan baik. | C39: A.5.37 | F39: GT1: Prosedur operasional yang didokumentasikan | GT2: No Value
A40: Q39 | B40: Guna menunjang keamanan dan keandalan sistem informasi organisasi, diperlukan pengelolaan kepatuhan terhadap kebijakan dan standar keamanan informasi yang memadai pada seluruh aspek operasional yang terkait. Mekanisme tersebut mencakup memastikan kepatuhan terhadap kebijakan, aturan, dan standar keamanan informasi organisasi serta pengendalian terhadap potensi risiko yang dapat mengganggu operasional. Pada aspek lain, diperlukan penerapan tinjauan independen keamanan informasi yang terstruktur dan terdokumentasi dengan baik. Selain hal tersebut, pelaksanaan privasi dan perlindungan data pribadi perlu diintegrasikan ke dalam kerangka pengendalian yang telah ditetapkan. Pengendalian tersebut perlu didukung oleh komitmen seluruh unit kerja serta didokumentasikan dalam bentuk prosedur yang dapat ditinjau secara berkala. | C40: A.5.36 | D40: A.5.35 | E40: A.5.34 | F40: GT1: Kepatuhan terhadap kebijakan dan standar keamanan informasi | GT2: Tinjauan independen keamanan informasi | GT3: Privasi dan perlindungan data pribadi
...

Sheet Implicit Short
A1: query_id | B1: query | C1: ground_truth_ranked_1 | D1: ground_truth_ranked_2 | E1: ground_truth_ranked_3 | F1: Explanation Reasoning
A2: Q1 | B2: DTI mendeteksi beberapa komputer di fakultas yang terinfeksi setelah staf mengunduh lampiran email mencurigakan, namun tim keamanan tidak memiliki log aktivitas jaringan untuk melacak sejauh mana penyebarannya ke sistem lain di universitas. | C2: A.8.7 | D2: A.8.16 | F2: A.8.7 — Perlindungan terhadap malware A.8.16 — Aktivitas pemantauan GT3: No Value
A3: Q2 | B3: Sistem informasi akademik yang baru dikembangkan DTI belum memiliki mekanisme validasi input yang memadai untuk mencegah injeksi data berbahaya, sementara tim pengembang masih menunggu panduan resmi tentang standar keamanan yang harus diterapkan. Fitur autentikasi dua faktor belum terintegrasi dalam portal layanan mahasiswa meskipun sistem tersebut sudah menyimpan data pribadi dan rekam akademik ribuan mahasiswa. Dokumen teknis sistem juga tidak mencantumkan spesifikasi keamanan yang jelas terkait perlindungan data sensitif mahasiswa saat diakses melalui jaringan publik. | C3: A.8.26 | F3: A.8.26 — Persyaratan keamanan aplikasi GT2: No Value GT3: No Value
A4: Q3 | B4: Satu-satunya pintu masuk ke gedung Rektorat tidak memiliki pos penjagaan atau sistem pencatatan tamu, memungkinkan siapa saja masuk tanpa verifikasi. Ruang server DTI menggunakan kabel jaringan yang tergantung terbuka di koridor tanpa proteksi pipa atau duct. Kontrak kerjasama dengan penyedia layanan SIAKAD tidak memuat klausul tentang perlindungan data akademik dan tanggung jawab keamanan informasi. | C4: A.7.2 | D4: A.7.12 | E4: A.5.20 | F4: A.7.2 — Kontrol masuk fisik A.7.12 — Keamanan pengkabelan A.5.20 — Keamanan informasi dalam perjanjian pemasok
A5: Q4 | B5: DTI baru saja menyeleksi dan memverifikasi rekam jejak calon mitra pengembangan sistem akademik yang akan diberi akses ke lingkungan produksi universitas. Direktorat Sistem Informasi telah menerbitkan dokumen kebijakan yang mengatur standar perlindungan informasi dan keamanan teknologi informasi seluruh unit kerja. Kebijakan tersebut menjadi dasar pengambilan keputusan bagi seluruh pimpinan fakultas dan biro dalam menentukan arah perlindungan aset digital di lingkungan kampus. | C5: A.6.1 | D5: A.5.1 | F5: A.6.1 — Penyaringan A.5.1 — Kebijakan keamanan informasi GT3: No Value
A6: Q5 | B6: Saat terjadi pemadaman listrik total di gedung rektorat, staf Direktorat TIK membutuhkan akses darurat ke server pusat untuk memastikan kelangsungan layanan akademik tetap berjalan. Prosedur manual yang saat ini tersedia belum mencakup panduan terperinci tentang cara mengamankan data sensitif mahasiswa ketika sistem utama tidak dapat diakses. | C6: A.5.29 | F6: A.5.29 — Keamanan informasi selama gangguan GT2: No Value GT3: No Value
A7: Q6 | B7: Sistem informasi akademik yang berisi data nilai mahasiswa belum tercatat dalam daftar aset informasi resmi universitas, sehingga sulit dilakukan pelacakan ketika terjadi insiden kebocoran data. Staf pengajar yang pindah ke fakultas lain masih menyimpan file materi kuliah dan rekam mahasiswa bimbingan di perangkat pribadi tanpa adanya prosedur formal pengembalian atau penghapusan data institusi. Aplikasi portal keuangan mahasiswa diakses oleh petugas yang tidak memiliki kewenangan karena belum ada pembatasan penggunaan yang jelas terhadap informasi sensitif tersebut. | C7: A.5.10 | D7: A.5.11 | E7: A.5.9 | F7: A.5.10 — Penggunaan informasi dan aset terkait yang dapat diterima A.5.11 — Pengembalian aset A.5.9 — Inventarisasi informasi dan aset terkait lainnya
A8: Q7 | B8: DTI menemukan bahwa beberapa server di lingkungan fakultas masih menjalankan versi sistem operasi yang sudah tidak didukung vendor dan belum menerapkan patch keamanan terbaru. Hasil scanning rutin menunjukkan adanya perangkat endpoint yang terinfeksi perangkat perusak karena pengaturan antivirus belum dikonfigurasi secara terpusat untuk melakukan update definisi virus secara otomatis. Kondisi ini mengakibatkan perbedaan baseline keamanan antar server serta meningkatnya risiko serangan terhadap infrastruktur jaringan kampus. | C8: A.8.9 | D8: A.8.7 | F8: A.8.9 — Manajemen konfigurasi A.8.7 — Perlindungan terhadap malware GT3: No Value
A9: Q8 | B9: Selama pemeriksaan rutin terhadap infrastruktur sistem informasi di lingkungan universitas, tim teknis menemukan beberapa celah keamanan pada server aplikasi akademik yang belum ditambal sejak bulan lalu. Perlu ditetapkan prosedur baku untuk melakukan pemindaian berkala, identifikasi celah keamanan, dan pemasangan pembaruan keamanan secara terjadwal guna mencegah potensi serangan siber. | C9: A.8.8 | F9: A.8.8 — Manajemen kerentanan teknis GT2: No Value GT3: No Value
A10: Q9 | B10: Sistem informasi akademik fakultas mengalami penurunan performa signifikan ketika 5.000 mahasiswa mengakses KRS secara bersamaan, sementara pengembang aplikasi masih mempraktikkan hardcoding kredensial database langsung di file konfigurasi yang disimpan di repository publik tanpa enkripsi, dan proses login dosen masih mengizinkan akses tanpa verifikasi dua faktor meskipun mereka dapat mengakses nilai dan data pribadi ribuan mahasiswa. | C10: A.8.6 | D10: A.8.4 | E10: A.8.5 | F10: A.8.6 — Manajemen kapasitas A.8.4 — Akses ke kode sumber A.8.5 — Autentikasi yang aman
A11: Q10 | B11: Tim audit internal memerlukan akses ke lingkungan produksi sistem akademik untuk melakukan verifikasi kelengkapan data mahasiswa, namun prosedur saat ini belum mengatur mekanisme perlindungan data selama pengujian berlangsung. Insiden terakhir menunjukkan bahwa data uji yang digunakan selama simulasi audit masih mencakup informasi riil mahasiswa aktif tanpa pemisahan yang memadai. | C11: A.8.34 | D11: A.8.33 | F11: A.8.34 — Perlindungan sistem informasi selama pengujian audit A.8.33 — Informasi pengujian GT3: No Value
A12: Q11 | B12: Sistem informasi akademik mengalami downtime selama 6 jam setelah tim DTI melakukan migrasi server tanpa adanya dokumentasi rencana implementasi dan uji coba terlebih dahulu. Beberapa fakultas mengeluhkan proses registrasi ulang terganggu karena perubahan konfigurasi basis data dilakukan secara mendadak tanpa koordinasi dengan pemangku kepentingan terkait. | C12: A.8.32 | F12: A.8.32 — Manajemen perubahan GT2: No Value GT3: No Value
A13: Q12 | B13: Tim pengembang sistem akademik universitas baru menyadari bahwa selama ini modul fitur langsung diterapkan ke lingkungan utama tanpa melalui tahap uji coba terpisah, sementara akses administrator ke program utilitas sistem belum dicatat dalam log aktivitas dan pemasangan aplikasi pendukung masih dilakukan tanpa prosedur persetujuan formal dari Direktorat TIK. | C13: A.8.31 | D13: A.8.19 | E13: A.8.18 | F13: A.8.31 — Pemisahan lingkungan pengembangan, pengujian, dan produksi A.8.19 — Instalasi perangkat lunak pada sistem operasional A.8.18 — Penggunaan program utilitas istimewa
A14: Q13 | B14: Sistem informasi akademik yang dikelola oleh DTI dikembangkan melalui kontrak dengan vendor pihak ketiga, namun belum terdapat mekanisme formal untuk memverifikasi kepatuhan vendor terhadap standar keamanan siber universitas selama masa pengembangan. Proses pembangunan aplikasi berlangsung tanpa tahapan pengujian keamanan yang terstruktur mulai dari desain hingga implementasi, sehingga potensi kerentanan sistem baru tidak teridentifikasi sebelum digunakan di lingkungan produksi. | C14: A.8.30 | D14: A.8.25 | F14: A.8.30 — Pengembangan yang dialihdayakan A.8.25 — Siklus hidup pengembangan yang aman GT3: No Value
A15: Q14 | B15: Sistem informasi keuangan universitas masih dapat diakses oleh seluruh staf administrasi tanpa pembatasan berdasarkan kebutuhan tugas, sehingga memungkinkan pegawai non-keuangan melihat data anggaran dan rincian pengeluaran seluruh unit kerja. Dokumen tender dan kontrak vendor yang tersimpan di server pusat bisa diunduh oleh siapa saja yang memiliki jaringan kampus tanpa mekanisme otorisasi khusus. Laporan keuangan yang bersifat rahasia sering dibagikan melalui grup WhatsApp resmi biro tanpa enkripsi atau perlindungan akses yang memadai. | C15: A.8.3 | F15: A.8.3 — Pembatasan akses informasi GT2: No Value GT3: No Value
A16: Q15 | B16: Saat DTI mengembangkan portal integrasi layanan akademik baru, tim pengembang belum melakukan verifikasi kerentanan sebelum aplikasi tersebut di-deploy ke lingkungan produksi. Desain arsitektur sistem juga belum mempertimbangkan pemisahan zona keamanan yang memadai antara modul keuangan dan data mahasiswa yang sensitif. Source code aplikasi e-learning masih ditemukan beberapa celah keamanan umum seperti hardcoded credentials dan tidak adanya validasi input yang ketat. | C16: A.8.29 | D16: A.8.27 | E16: A.8.28 | F16: A.8.29 — Pengujian keamanan dalam pengembangan dan penerimaan A.8.27 — Prinsip rekayasa dan arsitektur sistem yang aman A.8.28 — Pengkodean yang aman
A17: Q16 | B17: Sistem informasi akademik universitas menerapkan penyandian data transkrip nilai dan data keuangan mahasiswa sebelum disimpan dalam basis data serta dikirim melalui jaringan ke Direktorat Akademik. Selama pengembangan aplikasi portal layanan pendidikan baru, tim pengembang memastikan seluruh fitur login, validasi input, dan pengelolaan data sensitif telah memenuhi standar keamanan sesuai kebijakan institusi sebelum diimplementasikan di lingkungan produksi. | C17: A.8.24 | D17: A.8.26 | F17: A.8.24 — Penggunaan kriptografi A.8.26 — Persyaratan keamanan aplikasi GT3: No Value
A18: Q17 | B18: Pada periode semester genap 2023/2024, DTI Universitas Airlangga mencatat lonjakan trafik jaringan yang tidak wajar menuju kategori situs perjudian dan konten berbahaya selama jam operasional kampus. Tim IT mendeteksi bahwa 45% penggunaan bandwidth akademik tersita oleh aktivitas browsing yang tidak berkaitan dengan keperluan pendidikan, sehingga mengganggu stabilitas layanan e-learning dan sistem informasi akademik. | C18: A.8.23 | F18: A.8.23 — Penyaringan web GT2: No Value GT3: No Value
A19: Q18 | B19: Sistem akademik yang diakses mahasiswa berada di segmen jaringan yang terpisah dengan server database keuangan untuk mencegah penyebaran ancaman antar-area. DTI belum mengaktifkan pembatasan akses berdasarkan port dan protokol pada perangkat firewall yang menghubungkan jaringan kampus dengan internet. Layanan jaringan di fakultas masih berjalan tanpa konfigurasi enkripsi yang memadai untuk melindungi data sensitif selama transmisi antar-unit. | C19: A.8.22 | D19: A.8.20 | E19: A.8.21 | F19: A.8.22 — Pemisahan jaringan A.8.20 — Keamanan jaringan A.8.21 — Keamanan layanan jaringan
A20: Q19 | B20: Sistem informasi akademik di universitas masih mengizinkan administrator untuk memodifikasi nilai mahasiswa tanpa adanya persetujuan dua tahap dari pihak lain. Selain itu, tidak semua aktivitas login dan perubahan data yang dilakukan oleh administrator tersebut tercatat secara otomatis di sistem. Kondisi ini menyebabkan jejak audit hilang sehingga sulit dilakukan pelacakan jika terjadi penyimpangan pada data nilai mahasiswa. | C20: A.8.2 | D20: A.8.15 | F20: A.8.2 — Hak akses istimewa A.8.15 — Pencatatan log GT3: No Value
A21: Q20 | B21: Sistem informasi akademik dan aplikasi keuangan di lingkungan universitas menunjukkan perbedaan waktu pencatatan transaksi hingga mencapai beberapa menit, sehingga menyulitkan tim audit saat melakukan rekonsiliasi data antar sistem. Pada saat dilakukan investigasi insiden keamanan jaringan, ditemukan bahwa log aktivitas dari server berbeda memiliki timestamp yang tidak konsisten dan sulit dipastikan urutan kejadiannya.</arg_value>Selama audit sistem informasi akademik ditemukan selisih waktu lima belas menit antara server aplikasi dan database yang menyebabkan ketidaksesuaian pada timestamp log aktivitas mahasiswa saat proses registrasi online. | C21: A.8.17 | F21: A.8.17 — Sinkronisasi jam GT2: No Value GT3: No Value
A22: Q21 | B22: Saat server aplikasi di DTI mengalami kerusakan hardware dua bulan lalu, tim IT tidak dapat memulihkan layanan karena belum menyediakan server cadangan yang dapat berjalan segera setelah terjadi kegagalan. Setelah diperiksa lebih lanjut, data transaksi keuangan tiga bulan terakhir tidak dapat dikembalikan karena proses pencadangan otomatis belum diimplementasikan dengan jadwal yang teratur. Selain itu, ditemukan bahwa berkas rekam akademik mahasiswa yang telah lulus masih tersimpan di server produksi padahal sudah lebih dari lima tahun, tanpa ada prosedur penghapusan yang jelas. | C22: A.8.14 | D22: A.8.13 | E22: A.8.10 | F22: A.8.14 — Redundansi fasilitas pemrosesan informasi A.8.13 — Backup informasi A.8.10 — Penghapusan informasi
A23: Q22 | B23: DTI mendeteksi adanya upaya transfer data mahasiswa berupa file CSV yang tidak terenkripsi melalui aplikasi chatting pribadi oleh staf administrasi fakultas. Sementara itu, Direktorat Akademik menemukan bahwa basis data ujian online masih menampilkan nomor induk kependudukan dan nilai lengkap secara utuh tanpa masking kepada semua dosen penguji. | C23: A.8.12 | D23: A.8.11 | F23: A.8.12 — Pencegahan kebocoran data A.8.11 — Penyamaran data GT3: No Value
A24: Q23 | B24: DTI mencatat bahwa sebagian besar perangkat laptop dan PC milik staf administrasi serta dosen masih berjalan dengan sistem operasi Windows 7 yang tidak lagi mendapatkan dukungan pembaruan keamanan. Penggunaan perangkat kerja pribadi untuk mengakses portal akademik dan email institusi terus meningkat tanpa adanya standar konfigurasi keamanan yang jelas. Unit kerja juga belum memiliki kebijakan pelarangan penggunaan media penyimpanan data eksternal seperti flashdisk pada komputer laboratorium dan perangkat milik institusi. | C24: A.8.1 | F24: A.8.1 — Perangkat titik akhir pengguna GT2: No Value GT3: No Value
A25: Q24 | B25: Seorang dosen di Fakultas Teknik meninggalkan laptop institusi tanpa pengawasan di mobilnya yang terparkir di area publik selama menghadiri rapat koordinasi luar kampus, sementara staf administrasi di biro akademik masih sering menyimpan dokumen kontrak kerja sama dengan vendor berbasis kertas di atas meja kerja yang dapat diakses siapa saja yang lewal area resepsionis. | C25: A.7.9 | D25: A.7.8 | E25: A.7.7 | F25: A.7.9 — Keamanan aset di luar lokasi A.7.8 — Penempatan dan perlindungan peralatan A.7.7 — Meja bersih dan layar bersih
A26: Q25 | B26: Tim audit menemukan pintu masuk ruang server DTI yang sering dibiarkan terbuka tanpa pengawasan petugas keamanan, memungkinkan siapa saja leluasa masuk ke area penyimpanan perangkat IT. Selain itu, ruangan tersebut belum dilengkapi dengan sistem kunci elektronik maupun pencatatan digital untuk memantau siapa saja yang keluar masuk area sensitif tersebut. | C26: A.7.6 | D26: A.7.3 | F26: A.7.6 — Bekerja di area aman A.7.3 — Mengamankan kantor, ruangan, dan fasilitas GT3: No Value
A27: Q26 | B27: DTI melaporkan bahwa ruang server utama di gedung rektorat saat ini bersebelahan langsung dengan dapur katering dan jalur pipa air gedung, tanpa adanya detektor asap atau sistem pemadam kebakaran otomatis yang terpasang. Selain itu, panel listrik dan perangkat jaringan yang berada di lantai dasar gedung fakultas tidak memiliki pelindung waterproof meskipun lokasi tersebut sering tergenang air saat hujan deras. | C27: A.7.5 | F27: A.7.5 — Perlindungan terhadap ancaman fisik dan lingkungan GT2: No Value GT3: No Value
A28: Q27 | B28: Tim keamanan gedung melaporkan bahwa beberapa titik akses di area gedung rektorat dan fakultas sering ditemukan dalam kondisi tidak terkunci pada jam di luar jam operasional kampus. Kamera CCTV yang seharusnya memantau pergerakan di pintu masuk utama dan area parkir tidak berfungsi secara optimal sehingga kejadian-kejadian di luar jam kerja sulit untuk dideteksi. Pagar pembatas di sisi belakang area kampus yang berbatasan dengan jalan umum masih memiliki celah yang memungkinkan orang yang tidak berkepentingan dapat masuk ke lingkungan kampus tanpa melalui pos penjagaan. | C28: A.7.4 | D28: A.7.2 | E28: A.7.1 | F28: A.7.4 — Pemantauan keamanan fisik A.7.2 — Kontrol masuk fisik A.7.1 — Perimeter keamanan fisik
A29: Q28 | B29: DTI Universitas Negeri Malang akan memusnahkan 50 unit komputer desktop bekas dari laboratorium komputer yang telah mencapai masa pakai 7 tahun serta menghancurkan 25 hard disk eksternal yang menyimpan backup data keuangan tahun 2015-2020 karena sudah tidak digunakan lagi dalam operasional sistem informasi keuangan. Proses pemusnahan perangkat keras dan media penyimpanan ini memerlukan dokumentasi resmi yang disahkan oleh Kepala Biro Umum dan Kepala DTI untuk memastikan data sensitif di dalamnya tidak dapat dipulihkan atau disalahgunakan oleh pihak yang tidak bertanggung jawab. | C29: A.7.14 | D29: A.7.10 | F29: A.7.14 — Pembuangan atau penggunaan kembali peralatan secara aman A.7.10 — Media penyimpanan GT3: No Value
A30: Q29 | B30: DTI melaporkan bahwa tiga unit server di ruang server gedung A belum pernah dilakukan pembersihan debu dan pengecekan fisik sejak dioperasikan dua tahun lalu. Kondisi ini menyebabkan suhu perangatan meningkat dan muncul indikasi kerusakan pada kipas pendingin. Dokumentasi jadwal perawatan rutin untuk perangkat keras tersebut juga tidak tersedia di bagian inventaris. | C30: A.7.13 | F30: A.7.13 — Pemeliharaan peralatan GT2: No Value GT3: No Value
A31: Q30 | B31: DTI membutuhkan pemetaan jalur kabel jaringan dan dokumentasi utilitas pendukung di gedung pusat data untuk memastikan pemeliharaan infrastruktur dapat dilakukan dengan cepat saat terjadi gangguan. Tim teknis belum memiliki prosedur baku untuk mengantisipasi krisis akibat kegagalan sistem pendingin atau gangguan pasokan listrik yang berpotensi menghentikan layanan akademik dan administrasi secara menyeluruh. | C31: A.7.11 | D31: A.7.12 | E31: A.5.30 | F31: A.7.11 — Utilitas pendukung A.7.12 — Keamanan pengkabelan A.5.30 — Kesiapan TIK untuk kelangsungan bisnis
A32: Q31 | B32: Pada saat proses pengumuman hasil ujian skripsi secara online, sistem portal akademik mengalami gangguan teknis yang menyebabkan data nilai beberapa mahasiswa dapat diakses oleh pihak lain yang tidak berkepentingan. Petugas keamanan sistem baru melaporkan kejadian tersebut ke pimpinan fakultas dua hari setelah kejadian, sementara staf administrasi yang menangani data nilai tersebut belum menandatangani perjanjian tertulis mengenai kerahasiaan informasi akademik. | C32: A.6.8 | D32: A.6.6 | F32: A.6.8 — Pelaporan peristiwa keamanan informasi A.6.6 — Perjanjian kerahasiaan atau non-disclosure GT3: No Value
A33: Q32 | B33: Dalam beberapa bulan terakhir, DTI mencatat peningkatan signifikan jumlah dosen dan staf administrasi yang mengakses sistem akademik dan server universitas dari luar kampus menggunakan jaringan internet pribadi mereka. Namun, ditemukan bahwa tidak seluruh aktivitas penggunaan jaringan tersebut dilindungi dengan koneksi terenkripsi atau mekanisme keamanan yang memadai untuk menjaga kerahasiaan data institusi. | C33: A.6.7 | F33: A.6.7 — Bekerja jarak jauh GT2: No Value GT3: No Value
A34: Q33 | B34: Saat proses mutasi dan purna tugas pegawai di Direktorat SDM, DTI belum menerima pemberitahuan resmi untuk pencabutan akses ke sistem informasi keuangan dan portal akademik, sehingga mantan pegawai masih dapat login menggunakan akun institusi. Pada saat yang sama, kontrak kerja tenaga admin baru belum memuat kesepakatan tertulis mengenai kewajiban kerahasiaan terhadap data mahasiswa dan sanksi pelanggaran. Selain itu, unit kerja belum memiliki program pelatihan rutin tentang keamanan informasi bagi pegawai yang baru diangkat atau dipindah tugas. | C34: A.6.5 | D34: A.6.2 | E34: A.6.3 | F34: A.6.5 — Tanggung jawab setelah pemutusan atau perubahan hubungan kerja A.6.2 — Syarat dan ketentuan ketenagakerjaan A.6.3 — Kesadaran, pendidikan, dan pelatihan keamanan informasi
A35: Q34 | B35: Staf DTI yang mengakses data rekam akademik tanpa otorisasi untuk kepentingan pribadi hanya mendapatkan surat peringatan tertulis tanpa dijelaskan konsekuensi lanjutan dan tanpa pencatatan resmi di file kepegawaian. Selain itu, sistem rekrutmen tenaga teknis di fakultas belum memverifikasi kredensial akademik dan cek riwayat hukum sebelum diberikan akses ke sistem informasi keuangan dan data mahasiswa. | C35: A.6.4 | D35: A.6.1 | F35: A.6.4 — Proses pendisiplinan A.6.1 — Penyaringan GT3: No Value
